Workbook

Sheet 使い方
A1: 残響時間計算シート（課題：表1 建物の内装計画と残響時間計算表）
A3: ■ シート構成
A4: 材料DB …… 材料名と各周波数の吸音率α。ここを書き換えると全シートの計算に自動反映されます。
A5: 自分の計画 …… 自分の建物（18m×14m×高さ10m、300席、V=2520m³）の計算。【仮】と書いた面積は図面で確認して直すこと。
A6: p7例題_検算 …… p.7表1をそのまま再現し、資料の答えと一致することを確認するシート（触らなくてOK）。
A8: ■ 色の意味
A9: 黄色セル＋青文字 = 手で入力するセル（部位・材料・区分・面積・室容積など）
A10: 白セル＋黒文字 = 自動計算（数式）。触らないでください。
A11: 緑セル = 最終結果（総吸音力・残響時間）
A13: ■ 計算式（p.6）
A14: Sα = 面積S × 吸音率α 総吸音力 A = ΣSα 残響時間 T = 0.16V / A（Sabine式）
A15: 区分「共通」=空席・満席どちらにも入る面 / 「空席」=空席時だけ入る（椅子のみ）/ 「満席」=満席時だけ入る（椅子＋人）
... A24: 5. 表と下のグラフ（＝図3相当）をコピーしてレポートに貼り付け（「図として貼り付け」がきれいです）

Sheet 自分の計画
A1: 残響時間計算表（自分の計画） 黄色セルを変えると結果とグラフが自動で変わります
A2: 表1 建物の内装計画と残響時間計算表
A4: 部位 | B4: 仕上げ材料 | C4: 区分 | D4: 面積[m²] | E4: 125Hz | G4: 250Hz | I4: 500Hz | K4: 1kHz | M4: 2kHz | O4: 4kHz | Q4: 面積の根拠・メモ
E5: α | F5: Sα | G5: α | H5: Sα | I5: α | J5: Sα | K5: α | L5: Sα | M5: α | N5: Sα | O5: α | P5: Sα
A6: 床（通路） | B6: [09] タフテッドカーペット(パイル長3.5-8) | C6: 共通 | D6: =252-D15 -> 102 | E6: =IF($B6="","",IFERROR(INDEX(材料DB!C$5:C$130,MATCH($B6,材料DB!$B$5:$B$130,0)),"材料なし")) -> 0.05 | F6: =IF(OR($B6="",$D6=""),"",IFERROR($D6*E6,"")) -> 5.1 | G6: =IF($B6="","",IFERROR(INDEX(材料DB!D$5:D$130,MATCH($B6,材料DB!$B$5:$B$130,0)),"材料なし")) -> 0.08 | H6: =IF(OR($B6="",$D6=""),"",IFERROR($D6*G6,"")) -> 8.16 | I6: =IF($B6="","",IFERROR(INDEX(材料DB!E$5:E$130,MATCH($B6,材料DB!$B$5:$B$130,0)),"材料なし")) -> 0.2 | J6: =IF(OR($B6="",$D6=""),"",IFERROR($D6*I6,"")) -> 20.4 | K6: =IF($B6="","",IFERROR(INDEX(材料DB!F$5:F$130,MATCH($B6,材料DB!$B$5:$B$130,0)),"材料なし")) -> 0.45 | L6: =IF(OR($B6="",$D6=""),"",IFERROR($D6*K6,"")) -> 45.9 | M6: =IF($B6="","",IFERROR(INDEX(材料DB!G$5:G$130,MATCH($B6,材料DB!$B$5:$B$130,0)),"材料なし")) -> 0.5 | N6: =IF(OR($B6="",$D6=""),"",IFERROR($D6*M6,"")) -> 51 | O6: =IF($B6="","",IFERROR(INDEX(材料DB!H$5:H$130,MATCH($B6,材料DB!$B$5:$B$130,0)),"材料なし")) -> 0.5 | P6: =IF(OR($B6="",$D6=""),"",IFERROR($D6*O6,"")) -> 51 | Q6: 床252m²から客席部分を引いた残り
A7: 天井 | B7: [19] Wood Panel 9 AS_90以上 | C7: 共通 | D7: =252-D8 -> 234 | E7: =IF($B7="","",IFERROR(INDEX(材料DB!C$5:C$130,MATCH($B7,材料DB!$B$5:$B$130,0)),"材料なし")) -> 0.2 | F7: =IF(OR($B7="",$D7=""),"",IFERROR($D7*E7,"")) -> 46.8 | G7: =IF($B7="","",IFERROR(INDEX(材料DB!D$5:D$130,MATCH($B7,材料DB!$B$5:$B$130,0)),"材料なし")) -> 0.12 | H7: =IF(OR($B7="",$D7=""),"",IFERROR($D7*G7,"")) -> 28.08 | I7: =IF($B7="","",IFERROR(INDEX(材料DB!E$5:E$130,MATCH($B7,材料DB!$B$5:$B$130,0)),"材料なし")) -> 0.08 | J7: =IF(OR($B7="",$D7=""),"",IFERROR($D7*I7,"")) -> 18.72 | K7: =IF($B7="","",IFERROR(INDEX(材料DB!F$5:F$130,MATCH($B7,材料DB!$B$5:$B$130,0)),"材料なし")) -> 0.07 | L7: =IF(OR($B7="",$D7=""),"",IFERROR($D7*K7,"")) -> 16.38 | M7: =IF($B7="","",IFERROR(INDEX(材料DB!G$5:G$130,MATCH($B7,材料DB!$B$5:$B$130,0)),"材料なし")) -> 0.07 | N7: =IF(OR($B7="",$D7=""),"",IFERROR($D7*M7,"")) -> 16.38 | O7: =IF($B7="","",IFERROR(INDEX(材料DB!H$5:H$130,MATCH($B7,材料DB!$B$5:$B$130,0)),"材料なし")) -> 0.08 | P7: =IF(OR($B7="",$D7=""),"",IFERROR($D7*O7,"")) -> 18.72 | Q7: 天井252m²から投光室開口を引いた残り
A8: 天井投光室 | B8: [61] 開口部(吸音材なし) | C8: 共通 | D8: =18*1 -> 18 | E8: =IF($B8="","",IFERROR(INDEX(材料DB!C$5:C$130,MATCH($B8,材料DB!$B$5:$B$130,0)),"材料なし")) -> 0.1 | F8: =IF(OR($B8="",$D8=""),"",IFERROR($D8*E8,"")) -> 1.8 | G8: =IF($B8="","",IFERROR(INDEX(材料DB!D$5:D$130,MATCH($B8,材料DB!$B$5:$B$130,0)),"材料なし")) -> 0.15 | H8: =IF(OR($B8="",$D8=""),"",IFERROR($D8*G8,"")) -> 2.7 | I8: =IF($B8="","",IFERROR(INDEX(材料DB!E$5:E$130,MATCH($B8,材料DB!$B$5:$B$130,0)),"材料なし")) -> 0.2 | J8: =IF(OR($B8="",$D8=""),"",IFERROR($D8*I8,"")) -> 3.6 | K8: =IF($B8="","",IFERROR(INDEX(材料DB!F$5:F$130,MATCH($B8,材料DB!$B$5:$B$130,0)),"材料なし")) -> 0.22 | L8: =IF(OR($B8="",$D8=""),"",IFERROR($D8*K8,"")) -> 3.96 | M8: =IF($B8="","",IFERROR(INDEX(材料DB!G$5:G$130,MATCH($B8,材料DB!$B$5:$B$130,0)),"材料なし")) -> 0.25 | N8: =IF(OR($B8="",$D8=""),"",IFERROR($D8*M8,"")) -> 4.5 | O8: =IF($B8="","",IFERROR(INDEX(材料DB!H$5:H$130,MATCH($B8,材料DB!$B$5:$B$130,0)),"材料なし")) -> 0.3 | P8: =IF(OR($B8="",$D8=""),"",IFERROR($D8*O8,"")) -> 5.4 | Q8: 【仮】幅18m×奥行1mのスリット開口と仮定→図面で確認
A9: 側壁 | B9: [88] リブ吸音構造(木リブ+木毛セメント板) スリット20 空気層300 | C9: 共通 | D9: =14*10*2-D13 -> 257.32 | E9: =IF($B9="","",IFERROR(INDEX(材料DB!C$5:C$130,MATCH($B9,材料DB!$B$5:$B$130,0)),"材料なし")) -> 0.45 | F9: =IF(OR($B9="",$D9=""),"",IFERROR($D9*E9,"")) -> 115.794 | G9: =IF($B9="","",IFERROR(INDEX(材料DB!D$5:D$130,MATCH($B9,材料DB!$B$5:$B$130,0)),"材料なし")) -> 0.5 | H9: =IF(OR($B9="",$D9=""),"",IFERROR($D9*G9,"")) -> 128.66 | I9: =IF($B9="","",IFERROR(INDEX(材料DB!E$5:E$130,MATCH($B9,材料DB!$B$5:$B$130,0)),"材料なし")) -> 0.37 | J9: =IF(OR($B9="",$D9=""),"",IFERROR($D9*I9,"")) -> 95.2084 | K9: =IF($B9="","",IFERROR(INDEX(材料DB!F$5:F$130,MATCH($B9,材料DB!$B$5:$B$130,0)),"材料なし")) -> 0.4 | L9: =IF(OR($B9="",$D9=""),"",IFERROR($D9*K9,"")) -> 102.928 | M9: =IF($B9="","",IFERROR(INDEX(材料DB!G$5:G$130,MATCH($B9,材料DB!$B$5:$B$130,0)),"材料なし")) -> 0.4 | N9: =IF(OR($B9="",$D9=""),"",IFERROR($D9*M9,"")) -> 102.928 | O9: =IF($B9="","",IFERROR(INDEX(材料DB!H$5:H$130,MATCH($B9,材料DB!$B$5:$B$130,0)),"材料なし")) -> 0.37 | P9: =IF(OR($B9="",$D9=""),"",IFERROR($D9*O9,"")) -> 95.2084 | Q9: 14m×10m×2面から扉を引いた残り
A10: 後壁 | B10: [48] PW5_アナアキ 6φ15+GW50 +AS90 | C10: 共通 | D10: =18*10-D14 -> 165 | E10: =IF($B10="","",IFERROR(INDEX(材料DB!C$5:C$130,MATCH($B10,材料DB!$B$5:$B$130,0)),"材料なし")) -> 0.2 | F10: =IF(OR($B10="",$D10=""),"",IFERROR($D10*E10,"")) -> 33 | G10: =IF($B10="","",IFERROR(INDEX(材料DB!D$5:D$130,MATCH($B10,材料DB!$B$5:$B$130,0)),"材料なし")) -> 0.45 | H10: =IF(OR($B10="",$D10=""),"",IFERROR($D10*G10,"")) -> 74.25 | I10: =IF($B10="","",IFERROR(INDEX(材料DB!E$5:E$130,MATCH($B10,材料DB!$B$5:$B$130,0)),"材料なし")) -> 0.8 | J10: =IF(OR($B10="",$D10=""),"",IFERROR($D10*I10,"")) -> 132 | K10: =IF($B10="","",IFERROR(INDEX(材料DB!F$5:F$130,MATCH($B10,材料DB!$B$5:$B$130,0)),"材料なし")) -> 0.6 | L10: =IF(OR($B10="",$D10=""),"",IFERROR($D10*K10,"")) -> 99 | M10: =IF($B10="","",IFERROR(INDEX(材料DB!G$5:G$130,MATCH($B10,材料DB!$B$5:$B$130,0)),"材料なし")) -> 0.4 | N10: =IF(OR($B10="",$D10=""),"",IFERROR($D10*M10,"")) -> 66 | O10: =IF($B10="","",IFERROR(INDEX(材料DB!H$5:H$130,MATCH($B10,材料DB!$B$5:$B$130,0)),"材料なし")) -> 0.3 | P10: =IF(OR($B10="",$D10=""),"",IFERROR($D10*O10,"")) -> 49.5 | Q10: 18m×10mから調光室ガラスを引いた残り（エコー防止で吸音）
A11: 前壁（舞台側） | B11: [19] Wood Panel 9 AS_90以上 | C11: 共通 | D11: =18*10-D12 -> 96 | E11: =IF($B11="","",IFERROR(INDEX(材料DB!C$5:C$130,MATCH($B11,材料DB!$B$5:$B$130,0)),"材料なし")) -> 0.2 | F11: =IF(OR($B11="",$D11=""),"",IFERROR($D11*E11,"")) -> 19.2 | G11: =IF($B11="","",IFERROR(INDEX(材料DB!D$5:D$130,MATCH($B11,材料DB!$B$5:$B$130,0)),"材料なし")) -> 0.12 | H11: =IF(OR($B11="",$D11=""),"",IFERROR($D11*G11,"")) -> 11.52 | I11: =IF($B11="","",IFERROR(INDEX(材料DB!E$5:E$130,MATCH($B11,材料DB!$B$5:$B$130,0)),"材料なし")) -> 0.08 | J11: =IF(OR($B11="",$D11=""),"",IFERROR($D11*I11,"")) -> 7.68 | K11: =IF($B11="","",IFERROR(INDEX(材料DB!F$5:F$130,MATCH($B11,材料DB!$B$5:$B$130,0)),"材料なし")) -> 0.07 | L11: =IF(OR($B11="",$D11=""),"",IFERROR($D11*K11,"")) -> 6.72 | M11: =IF($B11="","",IFERROR(INDEX(材料DB!G$5:G$130,MATCH($B11,材料DB!$B$5:$B$130,0)),"材料なし")) -> 0.07 | N11: =IF(OR($B11="",$D11=""),"",IFERROR($D11*M11,"")) -> 6.72 | O11: =IF($B11="","",IFERROR(INDEX(材料DB!H$5:H$130,MATCH($B11,材料DB!$B$5:$B$130,0)),"材料なし")) -> 0.08 | P11: =IF(OR($B11="",$D11=""),"",IFERROR($D11*O11,"")) -> 7.68 | Q11: 18m×10mからプロセニアム開口を引いた残り（反射面）
A12: プロセニアム開口 | B12: [64] プロセニアム開口 | C12: 共通 | D12: =12*7 -> 84 | E12: =IF($B12="","",IFERROR(INDEX(材料DB!C$5:C$130,MATCH($B12,材料DB!$B$5:$B$130,0)),"材料なし")) -> 0.3 | F12: =IF(OR($B12="",$D12=""),"",IFERROR($D12*E12,"")) -> 25.2 | G12: =IF($B12="","",IFERROR(INDEX(材料DB!D$5:D$130,MATCH($B12,材料DB!$B$5:$B$130,0)),"材料なし")) -> 0.35 | H12: =IF(OR($B12="",$D12=""),"",IFERROR($D12*G12,"")) -> 29.4 | I12: =IF($B12="","",IFERROR(INDEX(材料DB!E$5:E$130,MATCH($B12,材料DB!$B$5:$B$130,0)),"材料なし")) -> 0.4 | J12: =IF(OR($B12="",$D12=""),"",IFERROR($D12*I12,"")) -> 33.6 | K12: =IF($B12="","",IFERROR(INDEX(材料DB!F$5:F$130,MATCH($B12,材料DB!$B$5:$B$130,0)),"材料なし")) -> 0.45 | L12: =IF(OR($B12="",$D12=""),"",IFERROR($D12*K12,"")) -> 37.8 | M12: =IF($B12="","",IFERROR(INDEX(材料DB!G$5:G$130,MATCH($B12,材料DB!$B$5:$B$130,0)),"材料なし")) -> 0.5 | N12: =IF(OR($B12="",$D12=""),"",IFERROR($D12*M12,"")) -> 42 | O12: =IF($B12="","",IFERROR(INDEX(材料DB!H$5:H$130,MATCH($B12,材料DB!$B$5:$B$130,0)),"材料なし")) -> 0.55 | P12: =IF(OR($B12="",$D12=""),"",IFERROR($D12*O12,"")) -> 46.2
A13: 扉 | B13: [66] ドア(ビニールレザー) | C13: 共通 | D13: =6*1.8*2.1 -> 22.68 | E13: =IF($B13="","",IFERROR(INDEX(材料DB!C$5:C$130,MATCH($B13,材料DB!$B$5:$B$130,0)),"材料なし")) -> 0.1 | F13: =IF(OR($B13="",$D13=""),"",IFERROR($D13*E13,"")) -> 2.268 | G13: =IF($B13="","",IFERROR(INDEX(材料DB!D$5:D$130,MATCH($B13,材料DB!$B$5:$B$130,0)),"材料なし")) -> 0.15 | H13: =IF(OR($B13="",$D13=""),"",IFERROR($D13*G13,"")) -> 3.402 | I13: =IF($B13="","",IFERROR(INDEX(材料DB!E$5:E$130,MATCH($B13,材料DB!$B$5:$B$130,0)),"材料なし")) -> 0.2 | J13: =IF(OR($B13="",$D13=""),"",IFERROR($D13*I13,"")) -> 4.536 | K13: =IF($B13="","",IFERROR(INDEX(材料DB!F$5:F$130,MATCH($B13,材料DB!$B$5:$B$130,0)),"材料なし")) -> 0.25 | L13: =IF(OR($B13="",$D13=""),"",IFERROR($D13*K13,"")) -> 5.67 | M13: =IF($B13="","",IFERROR(INDEX(材料DB!G$5:G$130,MATCH($B13,材料DB!$B$5:$B$130,0)),"材料なし")) -> 0.3 | N13: =IF(OR($B13="",$D13=""),"",IFERROR($D13*M13,"")) -> 6.804 | O13: =IF($B13="","",IFERROR(INDEX(材料DB!H$5:H$130,MATCH($B13,材料DB!$B$5:$B$130,0)),"材料なし")) -> 0.3 | P13: =IF(OR($B13="",$D13=""),"",IFERROR($D13*O13,"")) -> 6.804 | Q13: 【仮】両開き扉 1.8m×2.1m×6か所→図面で確認
A14: 音響・調光室 | B14: [05] ガラス窓(大版) | C14: 共通 | D14: =10*1.5 -> 15 | E14: =IF($B14="","",IFERROR(INDEX(材料DB!C$5:C$130,MATCH($B14,材料DB!$B$5:$B$130,0)),"材料なし")) -> 0.18 | F14: =IF(OR($B14="",$D14=""),"",IFERROR($D14*E14,"")) -> 2.7 | G14: =IF($B14="","",IFERROR(INDEX(材料DB!D$5:D$130,MATCH($B14,材料DB!$B$5:$B$130,0)),"材料なし")) -> 0.06 | H14: =IF(OR($B14="",$D14=""),"",IFERROR($D14*G14,"")) -> 0.9 | I14: =IF($B14="","",IFERROR(INDEX(材料DB!E$5:E$130,MATCH($B14,材料DB!$B$5:$B$130,0)),"材料なし")) -> 0.04 | J14: =IF(OR($B14="",$D14=""),"",IFERROR($D14*I14,"")) -> 0.6 | K14: =IF($B14="","",IFERROR(INDEX(材料DB!F$5:F$130,MATCH($B14,材料DB!$B$5:$B$130,0)),"材料なし")) -> 0.03 | L14: =IF(OR($B14="",$D14=""),"",IFERROR($D14*K14,"")) -> 0.45 | M14: =IF($B14="","",IFERROR(INDEX(材料DB!G$5:G$130,MATCH($B14,材料DB!$B$5:$B$130,0)),"材料なし")) -> 0.02 | N14: =IF(OR($B14="",$D14=""),"",IFERROR($D14*M14,"")) -> 0.3 | O14: =IF($B14="","",IFERROR(INDEX(材料DB!H$5:H$130,MATCH($B14,材料DB!$B$5:$B$130,0)),"材料なし")) -> 0.02 | P14: =IF(OR($B14="",$D14=""),"",IFERROR($D14*O14,"")) -> 0.3
A15: 椅子 | B15: [74] 椅子(モケット張) 劇場用 | C15: 空席 | D15: =300*0.5 -> 150 | E15: =IF($B15="","",IFERROR(INDEX(材料DB!C$5:C$130,MATCH($B15,材料DB!$B$5:$B$130,0)),"材料なし")) -> 0.14 | F15: =IF(OR($B15="",$D15=""),"",IFERROR($D15*E15,"")) -> 21 | G15: =IF($B15="","",IFERROR(INDEX(材料DB!D$5:D$130,MATCH($B15,材料DB!$B$5:$B$130,0)),"材料なし")) -> 0.25 | H15: =IF(OR($B15="",$D15=""),"",IFERROR($D15*G15,"")) -> 37.5 | I15: =IF($B15="","",IFERROR(INDEX(材料DB!E$5:E$130,MATCH($B15,材料DB!$B$5:$B$130,0)),"材料なし")) -> 0.3 | J15: =IF(OR($B15="",$D15=""),"",IFERROR($D15*I15,"")) -> 45 | K15: =IF($B15="","",IFERROR(INDEX(材料DB!F$5:F$130,MATCH($B15,材料DB!$B$5:$B$130,0)),"材料なし")) -> 0.3 | L15: =IF(OR($B15="",$D15=""),"",IFERROR($D15*K15,"")) -> 45 | M15: =IF($B15="","",IFERROR(INDEX(材料DB!G$5:G$130,MATCH($B15,材料DB!$B$5:$B$130,0)),"材料なし")) -> 0.3 | N15: =IF(OR($B15="",$D15=""),"",IFERROR($D15*M15,"")) -> 45 | O15: =IF($B15="","",IFERROR(INDEX(材料DB!H$5:H$130,MATCH($B15,材料DB!$B$5:$B$130,0)),"材料なし")) -> 0.3 | P15: =IF(OR($B15="",$D15=""),"",IFERROR($D15*O15,"")) -> 45 | Q15: 【仮】300席×0.5m²/席（客席部分の床面積）→図面で確認
A16: 椅子＋人 | B16: [78] 劇場用イス + ヒト | C16: 満席 | D16: =D15 -> 150 | E16: =IF($B16="","",IFERROR(INDEX(材料DB!C$5:C$130,MATCH($B16,材料DB!$B$5:$B$130,0)),"材料なし")) -> 0.25 | F16: =IF(OR($B16="",$D16=""),"",IFERROR($D16*E16,"")) -> 37.5 | G16: =IF($B16="","",IFERROR(INDEX(材料DB!D$5:D$130,MATCH($B16,材料DB!$B$5:$B$130,0)),"材料なし")) -> 0.35 | H16: =IF(OR($B16="",$D16=""),"",IFERROR($D16*G16,"")) -> 52.5 | I16: =IF($B16="","",IFERROR(INDEX(材料DB!E$5:E$130,MATCH($B16,材料DB!$B$5:$B$130,0)),"材料なし")) -> 0.4 | J16: =IF(OR($B16="",$D16=""),"",IFERROR($D16*I16,"")) -> 60 | K16: =IF($B16="","",IFERROR(INDEX(材料DB!F$5:F$130,MATCH($B16,材料DB!$B$5:$B$130,0)),"材料なし")) -> 0.4 | L16: =IF(OR($B16="",$D16=""),"",IFERROR($D16*K16,"")) -> 60 | M16: =IF($B16="","",IFERROR(INDEX(材料DB!G$5:G$130,MATCH($B16,材料DB!$B$5:$B$130,0)),"材料なし")) -> 0.4 | N16: =IF(OR($B16="",$D16=""),"",IFERROR($D16*M16,"")) -> 60 | O16: =IF($B16="","",IFERROR(INDEX(材料DB!H$5:H$130,MATCH($B16,材料DB!$B$5:$B$130,0)),"材料なし")) -> 0.4 | P16: =IF(OR($B16="",$D16=""),"",IFERROR($D16*O16,"")) -> 60 | Q16: 椅子と同じ面積
E17: =IF($B17="","",IFERROR(INDEX(材料DB!C$5:C$130,MATCH($B17,材料DB!$B$5:$B$130,0)),"材料なし")) | F17: =IF(OR($B17="",$D17=""),"",IFERROR($D17*E17,"")) | G17: =IF($B17="","",IFERROR(INDEX(材料DB!D$5:D$130,MATCH($B17,材料DB!$B$5:$B$130,0)),"材料なし")) | H17: =IF(OR($B17="",$D17=""),"",IFERROR($D17*G17,"")) | I17: =IF($B17="","",IFERROR(INDEX(材料DB!E$5:E$130,MATCH($B17,材料DB!$B$5:$B$130,0)),"材料なし")) | J17: =IF(OR($B17="",$D17=""),"",IFERROR($D17*I17,"")) | K17: =IF($B17="","",IFERROR(INDEX(材料DB!F$5:F$130,MATCH($B17,材料DB!$B$5:$B$130,0)),"材料なし")) | L17: =IF(OR($B17="",$D17=""),"",IFERROR($D17*K17,"")) | M17: =IF($B17="","",IFERROR(INDEX(材料DB!G$5:G$130,MATCH($B17,材料DB!$B$5:$B$130,0)),"材料なし")) | N17: =IF(OR($B17="",$D17=""),"",IFERROR($D17*M17,"")) | O17: =IF($B17="","",IFERROR(INDEX(材料DB!H$5:H$130,MATCH($B17,材料DB!$B$5:$B$130,0)),"材料なし")) | P17: =IF(OR($B17="",$D17=""),"",IFERROR($D17*O17,""))
E18: =IF($B18="","",IFERROR(INDEX(材料DB!C$5:C$130,MATCH($B18,材料DB!$B$5:$B$130,0)),"材料なし")) | F18: =IF(OR($B18="",$D18=""),"",IFERROR($D18*E18,"")) | G18: =IF($B18="","",IFERROR(INDEX(材料DB!D$5:D$130,MATCH($B18,材料DB!$B$5:$B$130,0)),"材料なし")) | H18: =IF(OR($B18="",$D18=""),"",IFERROR($D18*G18,"")) | I18: =IF($B18="","",IFERROR(INDEX(材料DB!E$5:E$130,MATCH($B18,材料DB!$B$5:$B$130,0)),"材料なし")) | J18: =IF(OR($B18="",$D18=""),"",IFERROR($D18*I18,"")) | K18: =IF($B18="","",IFERROR(INDEX(材料DB!F$5:F$130,MATCH($B18,材料DB!$B$5:$B$130,0)),"材料なし")) | L18: =IF(OR($B18="",$D18=""),"",IFERROR($D18*K18,"")) | M18: =IF($B18="","",IFERROR(INDEX(材料DB!G$5:G$130,MATCH($B18,材料DB!$B$5:$B$130,0)),"材料なし")) | N18: =IF(OR($B18="",$D18=""),"",IFERROR($D18*M18,"")) | O18: =IF($B18="","",IFERROR(INDEX(材料DB!H$5:H$130,MATCH($B18,材料DB!$B$5:$B$130,0)),"材料なし")) | P18: =IF(OR($B18="",$D18=""),"",IFERROR($D18*O18,""))
E19: =IF($B19="","",IFERROR(INDEX(材料DB!C$5:C$130,MATCH($B19,材料DB!$B$5:$B$130,0)),"材料なし")) | F19: =IF(OR($B19="",$D19=""),"",IFERROR($D19*E19,"")) | G19: =IF($B19="","",IFERROR(INDEX(材料DB!D$5:D$130,MATCH($B19,材料DB!$B$5:$B$130,0)),"材料なし")) | H19: =IF(OR($B19="",$D19=""),"",IFERROR($D19*G19,"")) | I19: =IF($B19="","",IFERROR(INDEX(材料DB!E$5:E$130,MATCH($B19,材料DB!$B$5:$B$130,0)),"材料なし")) | J19: =IF(OR($B19="",$D19=""),"",IFERROR($D19*I19,"")) | K19: =IF($B19="","",IFERROR(INDEX(材料DB!F$5:F$130,MATCH($B19,材料DB!$B$5:$B$130,0)),"材料なし")) | L19: =IF(OR($B19="",$D19=""),"",IFERROR($D19*K19,"")) | M19: =IF($B19="","",IFERROR(INDEX(材料DB!G$5:G$130,MATCH($B19,材料DB!$B$5:$B$130,0)),"材料なし")) | N19: =IF(OR($B19="",$D19=""),"",IFERROR($D19*M19,"")) | O19: =IF($B19="","",IFERROR(INDEX(材料DB!H$5:H$130,MATCH($B19,材料DB!$B$5:$B$130,0)),"材料なし")) | P19: =IF(OR($B19="",$D19=""),"",IFERROR($D19*O19,""))
E20: =IF($B20="","",IFERROR(INDEX(材料DB!C$5:C$130,MATCH($B20,材料DB!$B$5:$B$130,0)),"材料なし")) | F20: =IF(OR($B20="",$D20=""),"",IFERROR($D20*E20,"")) | G20: =IF($B20="","",IFERROR(INDEX(材料DB!D$5:D$130,MATCH($B20,材料DB!$B$5:$B$130,0)),"材料なし")) | H20: =IF(OR($B20="",$D20=""),"",IFERROR($D20*G20,"")) | I20: =IF($B20="","",IFERROR(INDEX(材料DB!E$5:E$130,MATCH($B20,材料DB!$B$5:$B$130,0)),"材料なし")) | J20: =IF(OR($B20="",$D20=""),"",IFERROR($D20*I20,"")) | K20: =IF($B20="","",IFERROR(INDEX(材料DB!F$5:F$130,MATCH($B20,材料DB!$B$5:$B$130,0)),"材料なし")) | L20: =IF(OR($B20="",$D20=""),"",IFERROR($D20*K20,"")) | M20: =IF($B20="","",IFERROR(INDEX(材料DB!G$5:G$130,MATCH($B20,材料DB!$B$5:$B$130,0)),"材料なし")) | N20: =IF(OR($B20="",$D20=""),"",IFERROR($D20*M20,"")) | O20: =IF($B20="","",IFERROR(INDEX(材料DB!H$5:H$130,MATCH($B20,材料DB!$B$5:$B$130,0)),"材料なし")) | P20: =IF(OR($B20="",$D20=""),"",IFERROR($D20*O20,""))
E21: =IF($B21="","",IFERROR(INDEX(材料DB!C$5:C$130,MATCH($B21,材料DB!$B$5:$B$130,0)),"材料なし")) | F21: =IF(OR($B21="",$D21=""),"",IFERROR($D21*E21,"")) | G21: =IF($B21="","",IFERROR(INDEX(材料DB!D$5:D$130,MATCH($B21,材料DB!$B$5:$B$130,0)),"材料なし")) | H21: =IF(OR($B21="",$D21=""),"",IFERROR($D21*G21,"")) | I21: =IF($B21="","",IFERROR(INDEX(材料DB!E$5:E$130,MATCH($B21,材料DB!$B$5:$B$130,0)),"材料なし")) | J21: =IF(OR($B21="",$D21=""),"",IFERROR($D21*I21,"")) | K21: =IF($B21="","",IFERROR(INDEX(材料DB!F$5:F$130,MATCH($B21,材料DB!$B$5:$B$130,0)),"材料なし")) | L21: =IF(OR($B21="",$D21=""),"",IFERROR($D21*K21,"")) | M21: =IF($B21="","",IFERROR(INDEX(材料DB!G$5:G$130,MATCH($B21,材料DB!$B$5:$B$130,0)),"材料なし")) | N21: =IF(OR($B21="",$D21=""),"",IFERROR($D21*M21,"")) | O21: =IF($B21="","",IFERROR(INDEX(材料DB!H$5:H$130,MATCH($B21,材料DB!$B$5:$B$130,0)),"材料なし")) | P21: =IF(OR($B21="",$D21=""),"",IFERROR($D21*O21,""))
E22: =IF($B22="","",IFERROR(INDEX(材料DB!C$5:C$130,MATCH($B22,材料DB!$B$5:$B$130,0)),"材料なし")) | F22: =IF(OR($B22="",$D22=""),"",IFERROR($D22*E22,"")) | G22: =IF($B22="","",IFERROR(INDEX(材料DB!D$5:D$130,MATCH($B22,材料DB!$B$5:$B$130,0)),"材料なし")) | H22: =IF(OR($B22="",$D22=""),"",IFERROR($D22*G22,"")) | I22: =IF($B22="","",IFERROR(INDEX(材料DB!E$5:E$130,MATCH($B22,材料DB!$B$5:$B$130,0)),"材料なし")) | J22: =IF(OR($B22="",$D22=""),"",IFERROR($D22*I22,"")) | K22: =IF($B22="","",IFERROR(INDEX(材料DB!F$5:F$130,MATCH($B22,材料DB!$B$5:$B$130,0)),"材料なし")) | L22: =IF(OR($B22="",$D22=""),"",IFERROR($D22*K22,"")) | M22: =IF($B22="","",IFERROR(INDEX(材料DB!G$5:G$130,MATCH($B22,材料DB!$B$5:$B$130,0)),"材料なし")) | N22: =IF(OR($B22="",$D22=""),"",IFERROR($D22*M22,"")) | O22: =IF($B22="","",IFERROR(INDEX(材料DB!H$5:H$130,MATCH($B22,材料DB!$B$5:$B$130,0)),"材料なし")) | P22: =IF(OR($B22="",$D22=""),"",IFERROR($D22*O22,""))
E23: =IF($B23="","",IFERROR(INDEX(材料DB!C$5:C$130,MATCH($B23,材料DB!$B$5:$B$130,0)),"材料なし")) | F23: =IF(OR($B23="",$D23=""),"",IFERROR($D23*E23,"")) | G23: =IF($B23="","",IFERROR(INDEX(材料DB!D$5:D$130,MATCH($B23,材料DB!$B$5:$B$130,0)),"材料なし")) | H23: =IF(OR($B23="",$D23=""),"",IFERROR($D23*G23,"")) | I23: =IF($B23="","",IFERROR(INDEX(材料DB!E$5:E$130,MATCH($B23,材料DB!$B$5:$B$130,0)),"材料なし")) | J23: =IF(OR($B23="",$D23=""),"",IFERROR($D23*I23,"")) | K23: =IF($B23="","",IFERROR(INDEX(材料DB!F$5:F$130,MATCH($B23,材料DB!$B$5:$B$130,0)),"材料なし")) | L23: =IF(OR($B23="",$D23=""),"",IFERROR($D23*K23,"")) | M23: =IF($B23="","",IFERROR(INDEX(材料DB!G$5:G$130,MATCH($B23,材料DB!$B$5:$B$130,0)),"材料なし")) | N23: =IF(OR($B23="",$D23=""),"",IFERROR($D23*M23,"")) | O23: =IF($B23="","",IFERROR(INDEX(材料DB!H$5:H$130,MATCH($B23,材料DB!$B$5:$B$130,0)),"材料なし")) | P23: =IF(OR($B23="",$D23=""),"",IFERROR($D23*O23,""))
E24: =IF($B24="","",IFERROR(INDEX(材料DB!C$5:C$130,MATCH($B24,材料DB!$B$5:$B$130,0)),"材料なし")) | F24: =IF(OR($B24="",$D24=""),"",IFERROR($D24*E24,"")) | G24: =IF($B24="","",IFERROR(INDEX(材料DB!D$5:D$130,MATCH($B24,材料DB!$B$5:$B$130,0)),"材料なし")) | H24: =IF(OR($B24="",$D24=""),"",IFERROR($D24*G24,"")) | I24: =IF($B24="","",IFERROR(INDEX(材料DB!E$5:E$130,MATCH($B24,材料DB!$B$5:$B$130,0)),"材料なし")) | J24: =IF(OR($B24="",$D24=""),"",IFERROR($D24*I24,"")) | K24: =IF($B24="","",IFERROR(INDEX(材料DB!F$5:F$130,MATCH($B24,材料DB!$B$5:$B$130,0)),"材料なし")) | L24: =IF(OR($B24="",$D24=""),"",IFERROR($D24*K24,"")) | M24: =IF($B24="","",IFERROR(INDEX(材料DB!G$5:G$130,MATCH($B24,材料DB!$B$5:$B$130,0)),"材料なし")) | N24: =IF(OR($B24="",$D24=""),"",IFERROR($D24*M24,"")) | O24: =IF($B24="","",IFERROR(INDEX(材料DB!H$5:H$130,MATCH($B24,材料DB!$B$5:$B$130,0)),"材料なし")) | P24: =IF(OR($B24="",$D24=""),"",IFERROR($D24*O24,""))
E25: =IF($B25="","",IFERROR(INDEX(材料DB!C$5:C$130,MATCH($B25,材料DB!$B$5:$B$130,0)),"材料なし")) | F25: =IF(OR($B25="",$D25=""),"",IFERROR($D25*E25,"")) | G25: =IF($B25="","",IFERROR(INDEX(材料DB!D$5:D$130,MATCH($B25,材料DB!$B$5:$B$130,0)),"材料なし")) | H25: =IF(OR($B25="",$D25=""),"",IFERROR($D25*G25,"")) | I25: =IF($B25="","",IFERROR(INDEX(材料DB!E$5:E$130,MATCH($B25,材料DB!$B$5:$B$130,0)),"材料なし")) | J25: =IF(OR($B25="",$D25=""),"",IFERROR($D25*I25,"")) | K25: =IF($B25="","",IFERROR(INDEX(材料DB!F$5:F$130,MATCH($B25,材料DB!$B$5:$B$130,0)),"材料なし")) | L25: =IF(OR($B25="",$D25=""),"",IFERROR($D25*K25,"")) | M25: =IF($B25="","",IFERROR(INDEX(材料DB!G$5:G$130,MATCH($B25,材料DB!$B$5:$B$130,0)),"材料なし")) | N25: =IF(OR($B25="",$D25=""),"",IFERROR($D25*M25,"")) | O25: =IF($B25="","",IFERROR(INDEX(材料DB!H$5:H$130,MATCH($B25,材料DB!$B$5:$B$130,0)),"材料なし")) | P25: =IF(OR($B25="",$D25=""),"",IFERROR($D25*O25,""))
A27: 全表面積 | D27: =SUMIF($C$6:$C$25,"共通",$D$6:$D$25) -> 994 | E27: m² | G27: 椅子含む: | I27: =D27+SUMIF($C$6:$C$25,"空席",$D$6:$D$25) -> 1144 | Q27: 椅子を除く（p.7と同じ数え方）。椅子の面積も含めた部屋の全表面積 →
A28: 室容積 V | D28: 2520 | E28: m³
A30: 総吸音力 A [m²] | C30: 空席時 | F30: =SUMIF($C$6:$C$25,"共通",F$6:F$25)+SUMIF($C$6:$C$25,"空席",F$6:F$25) -> 272.862 | H30: =SUMIF($C$6:$C$25,"共通",H$6:H$25)+SUMIF($C$6:$C$25,"空席",H$6:H$25) -> 324.572 | J30: =SUMIF($C$6:$C$25,"共通",J$6:J$25)+SUMIF($C$6:$C$25,"空席",J$6:J$25) -> 361.3444 | L30: =SUMIF($C$6:$C$25,"共通",L$6:L$25)+SUMIF($C$6:$C$25,"空席",L$6:L$25) -> 363.808 | N30: =SUMIF($C$6:$C$25,"共通",N$6:N$25)+SUMIF($C$6:$C$25,"空席",N$6:N$25) -> 341.632 | P30: =SUMIF($C$6:$C$25,"共通",P$6:P$25)+SUMIF($C$6:$C$25,"空席",P$6:P$25) -> 325.8124
C31: 満席時 | F31: =SUMIF($C$6:$C$25,"共通",F$6:F$25)+SUMIF($C$6:$C$25,"満席",F$6:F$25) -> 289.362 | H31: =SUMIF($C$6:$C$25,"共通",H$6:H$25)+SUMIF($C$6:$C$25,"満席",H$6:H$25) -> 339.572 | J31: =SUMIF($C$6:$C$25,"共通",J$6:J$25)+SUMIF($C$6:$C$25,"満席",J$6:J$25) -> 376.3444 | L31: =SUMIF($C$6:$C$25,"共通",L$6:L$25)+SUMIF($C$6:$C$25,"満席",L$6:L$25) -> 378.808 | N31: =SUMIF($C$6:$C$25,"共通",N$6:N$25)+SUMIF($C$6:$C$25,"満席",N$6:N$25) -> 356.632 | P31: =SUMIF($C$6:$C$25,"共通",P$6:P$25)+SUMIF($C$6:$C$25,"満席",P$6:P$25) -> 340.8124
A32: 残響時間 T [秒] | C32: 空席時 | F32: =IF(OR(F30=0,$D$28=""),"",0.16*$D$28/F30) -> 1.47767 | H32: =IF(OR(H30=0,$D$28=""),"",0.16*$D$28/H30) -> 1.2422513 | J32: =IF(OR(J30=0,$D$28=""),"",0.16*$D$28/J30) -> 1.115833 | L32: =IF(OR(L30=0,$D$28=""),"",0.16*$D$28/L30) -> 1.1082769 | N32: =IF(OR(N30=0,$D$28=""),"",0.16*$D$28/N30) -> 1.1802173 | P32: =IF(OR(P30=0,$D$28=""),"",0.16*$D$28/P30) -> 1.237522
C33: 満席時 | F33: =IF(OR(F31=0,$D$28=""),"",0.16*$D$28/F31) -> 1.3934103 | H33: =IF(OR(H31=0,$D$28=""),"",0.16*$D$28/H31) -> 1.1873771 | J33: =IF(OR(J31=0,$D$28=""),"",0.16*$D$28/J31) -> 1.0713591 | L33: =IF(OR(L31=0,$D$28=""),"",0.16*$D$28/L31) -> 1.0643915 | N33: =IF(OR(N31=0,$D$28=""),"",0.16*$D$28/N31) -> 1.1305772 | P33: =IF(OR(P31=0,$D$28=""),"",0.16*$D$28/P31) -> 1.1830555
A36: グラフ用（図3 予測された残響時間特性）
A37: 周波数 | B37: 空席時 | C37: 満席時
A38: 125 | B38: =F32 -> 1.47767 | C38: =F33 -> 1.3934103
A39: 250 | B39: =H32 -> 1.2422513 | C39: =H33 -> 1.1873771
A40: 500 | B40: =J32 -> 1.115833 | C40: =J33 -> 1.0713591
A41: 1k | B41: =L32 -> 1.1082769 | C41: =L33 -> 1.0643915
A42: 2k | B42: =N32 -> 1.1802173 | C42: =N33 -> 1.1305772
A43: 4k | B43: =P32 -> 1.237522 | C43: =P33 -> 1.1830555
A52: 最適残響時間のチェック（図1）
A53: 建物の用途 | D53: （ここに用途を記入）
...

Sheet 材料DB
A1: 材料DB（吸音率α）
A2: 出典：配布資料「各種材料の吸音率」No.1〜94（p.8〜10）。No.80〜94はリブ吸音構造体。自分で使う材料は空き行（黄色）に追加。材料名は重複させないこと（同じ『開口』でも場所で値が違うなら名前を変える）。
A4: No. | B4: 材料名 | C4: 125Hz | D4: 250Hz | E4: 500Hz | F4: 1kHz | G4: 2kHz | H4: 4kHz | I4: 出典・メモ
A5: 1 | B5: [01] コンクリート打ち放し モルタル・ペイント | C5: 0.01 | D5: 0.01 | E5: 0.02 | F5: 0.02 | G5: 0.03 | H5: 0.03 | I5: 配布資料「各種材料の吸音率」p.8〜10
A6: 2 | B6: [02] コンクリート 布クロス張り | C6: 0.03 | D6: 0.03 | E6: 0.03 | F6: 0.04 | G6: 0.06 | H6: 0.08 | I6: 配布資料「各種材料の吸音率」p.8〜10
A7: 3 | B7: [03] コンクリート プラスター5吹付 | C7: 0.04 | D7: 0.1 | E7: 0.17 | F7: 0.17 | G7: 0.19 | H7: 0.2 | I7: 配布資料「各種材料の吸音率」p.8〜10
A8: 4 | B8: [04] 軽量コンクリートブロック | C8: 0.12 | D8: 0.22 | E8: 0.2 | F8: 0.2 | G8: 0.23 | H8: 0.27 | I8: 配布資料「各種材料の吸音率」p.8〜10
A9: 5 | B9: [05] ガラス窓(大版) | C9: 0.18 | D9: 0.06 | E9: 0.04 | F9: 0.03 | G9: 0.02 | H9: 0.02 | I9: 配布資料「各種材料の吸音率」p.8〜10
A10: 6 | B10: [06] ガラスブロック | C10: 0.04 | D10: 0.04 | E10: 0.03 | F10: 0.03 | G10: 0.02 | H10: 0.02 | I10: 配布資料「各種材料の吸音率」p.8〜10
A11: 7 | B11: [07] 合成繊維カーペット | C11: 0.02 | D11: 0.03 | E11: 0.05 | F11: 0.08 | G11: 0.12 | H11: 0.15 | I11: 配布資料「各種材料の吸音率」p.8〜10
A12: 8 | B12: [08] タイルカーペット(パイル長3.5) | C12: 0.02 | D12: 0.05 | E12: 0.1 | F12: 0.2 | G12: 0.3 | H12: 0.4 | I12: 配布資料「各種材料の吸音率」p.8〜10
A13: 9 | B13: [09] タフテッドカーペット(パイル長3.5-8) | C13: 0.05 | D13: 0.08 | E13: 0.2 | F13: 0.45 | G13: 0.5 | H13: 0.5 | I13: 配布資料「各種材料の吸音率」p.8〜10
A14: 10 | B14: [10] スタイロ畳60(RCスラブ直敷) | C14: 0.26 | D14: 0.28 | E14: 0.3 | F14: 0.43 | G14: 0.35 | H14: 0.26 | I14: 配布資料「各種材料の吸音率」p.8〜10
A15: 11 | B15: [11] 本畳60(RCスラブ直敷) | C15: 0.28 | D15: 0.42 | E15: 0.32 | F15: 0.37 | G15: 0.5 | H15: 0.35 | I15: 配布資料「各種材料の吸音率」p.8〜10
A16: 12 | B16: [12] 本畳60(根太床下地) | C16: 0.15 | D16: 0.24 | E16: 0.28 | F16: 0.42 | G16: 0.47 | H16: 0.35 | I16: 配布資料「各種材料の吸音率」p.8〜10
... A98: 94 | B98: [94] リブ吸音構造(縦リブ+RW25) スリット30 空気層50 | C98: 0.2 | D98: 0.6 | E98: 0.75 | F98: 0.65 | G98: 0.7 | H98: 0.6 | I98: 配布資料「各種材料の吸音率」p.8〜10

Sheet p7例題_検算
A1: p.7 表1 の再現（検算用・編集不要）
A2: 表1 建物の内装計画と残響時間計算表
A4: 部位 | B4: 仕上げ材料 | C4: 区分 | D4: 面積[m²] | E4: 125Hz | G4: 250Hz | I4: 500Hz | K4: 1kHz | M4: 2kHz | O4: 4kHz | Q4: 面積の根拠・メモ
E5: α | F5: Sα | G5: α | H5: Sα | I5: α | J5: Sα | K5: α | L5: Sα | M5: α | N5: Sα | O5: α | P5: Sα
A6: 床 | B6: [07] 合成繊維カーペット | C6: 共通 | D6: 356 | E6: =IF($B6="","",IFERROR(INDEX(材料DB!C$5:C$130,MATCH($B6,材料DB!$B$5:$B$130,0)),"材料なし")) -> 0.02 | F6: =IF(OR($B6="",$D6=""),"",IFERROR($D6*E6,"")) -> 7.12 | G6: =IF($B6="","",IFERROR(INDEX(材料DB!D$5:D$130,MATCH($B6,材料DB!$B$5:$B$130,0)),"材料なし")) -> 0.03 | H6: =IF(OR($B6="",$D6=""),"",IFERROR($D6*G6,"")) -> 10.68 | I6: =IF($B6="","",IFERROR(INDEX(材料DB!E$5:E$130,MATCH($B6,材料DB!$B$5:$B$130,0)),"材料なし")) -> 0.05 | J6: =IF(OR($B6="",$D6=""),"",IFERROR($D6*I6,"")) -> 17.8 | K6: =IF($B6="","",IFERROR(INDEX(材料DB!F$5:F$130,MATCH($B6,材料DB!$B$5:$B$130,0)),"材料なし")) -> 0.08 | L6: =IF(OR($B6="",$D6=""),"",IFERROR($D6*K6,"")) -> 28.48 | M6: =IF($B6="","",IFERROR(INDEX(材料DB!G$5:G$130,MATCH($B6,材料DB!$B$5:$B$130,0)),"材料なし")) -> 0.12 | N6: =IF(OR($B6="",$D6=""),"",IFERROR($D6*M6,"")) -> 42.72 | O6: =IF($B6="","",IFERROR(INDEX(材料DB!H$5:H$130,MATCH($B6,材料DB!$B$5:$B$130,0)),"材料なし")) -> 0.15 | P6: =IF(OR($B6="",$D6=""),"",IFERROR($D6*O6,"")) -> 53.4
A7: 天井 | B7: [17] Wood Panel 6 AS_90以上 | C7: 共通 | D7: 423 | E7: =IF($B7="","",IFERROR(INDEX(材料DB!C$5:C$130,MATCH($B7,材料DB!$B$5:$B$130,0)),"材料なし")) -> 0.22 | F7: =IF(OR($B7="",$D7=""),"",IFERROR($D7*E7,"")) -> 93.06 | G7: =IF($B7="","",IFERROR(INDEX(材料DB!D$5:D$130,MATCH($B7,材料DB!$B$5:$B$130,0)),"材料なし")) -> 0.13 | H7: =IF(OR($B7="",$D7=""),"",IFERROR($D7*G7,"")) -> 54.99 | I7: =IF($B7="","",IFERROR(INDEX(材料DB!E$5:E$130,MATCH($B7,材料DB!$B$5:$B$130,0)),"材料なし")) -> 0.1 | J7: =IF(OR($B7="",$D7=""),"",IFERROR($D7*I7,"")) -> 42.3 | K7: =IF($B7="","",IFERROR(INDEX(材料DB!F$5:F$130,MATCH($B7,材料DB!$B$5:$B$130,0)),"材料なし")) -> 0.07 | L7: =IF(OR($B7="",$D7=""),"",IFERROR($D7*K7,"")) -> 29.61 | M7: =IF($B7="","",IFERROR(INDEX(材料DB!G$5:G$130,MATCH($B7,材料DB!$B$5:$B$130,0)),"材料なし")) -> 0.07 | N7: =IF(OR($B7="",$D7=""),"",IFERROR($D7*M7,"")) -> 29.61 | O7: =IF($B7="","",IFERROR(INDEX(材料DB!H$5:H$130,MATCH($B7,材料DB!$B$5:$B$130,0)),"材料なし")) -> 0.08 | P7: =IF(OR($B7="",$D7=""),"",IFERROR($D7*O7,"")) -> 33.84 | Q7: 資料は「板張り6+空気層100」
A8: 天井投光室 | B8: [61] 開口部(吸音材なし) | C8: 共通 | D8: 43 | E8: =IF($B8="","",IFERROR(INDEX(材料DB!C$5:C$130,MATCH($B8,材料DB!$B$5:$B$130,0)),"材料なし")) -> 0.1 | F8: =IF(OR($B8="",$D8=""),"",IFERROR($D8*E8,"")) -> 4.3 | G8: =IF($B8="","",IFERROR(INDEX(材料DB!D$5:D$130,MATCH($B8,材料DB!$B$5:$B$130,0)),"材料なし")) -> 0.15 | H8: =IF(OR($B8="",$D8=""),"",IFERROR($D8*G8,"")) -> 6.45 | I8: =IF($B8="","",IFERROR(INDEX(材料DB!E$5:E$130,MATCH($B8,材料DB!$B$5:$B$130,0)),"材料なし")) -> 0.2 | J8: =IF(OR($B8="",$D8=""),"",IFERROR($D8*I8,"")) -> 8.6 | K8: =IF($B8="","",IFERROR(INDEX(材料DB!F$5:F$130,MATCH($B8,材料DB!$B$5:$B$130,0)),"材料なし")) -> 0.22 | L8: =IF(OR($B8="",$D8=""),"",IFERROR($D8*K8,"")) -> 9.46 | M8: =IF($B8="","",IFERROR(INDEX(材料DB!G$5:G$130,MATCH($B8,材料DB!$B$5:$B$130,0)),"材料なし")) -> 0.25 | N8: =IF(OR($B8="",$D8=""),"",IFERROR($D8*M8,"")) -> 10.75 | O8: =IF($B8="","",IFERROR(INDEX(材料DB!H$5:H$130,MATCH($B8,材料DB!$B$5:$B$130,0)),"材料なし")) -> 0.3 | P8: =IF(OR($B8="",$D8=""),"",IFERROR($D8*O8,"")) -> 12.9
A9: 壁面 | B9: [19] Wood Panel 9 AS_90以上 | C9: 共通 | D9: 240 | E9: =IF($B9="","",IFERROR(INDEX(材料DB!C$5:C$130,MATCH($B9,材料DB!$B$5:$B$130,0)),"材料なし")) -> 0.2 | F9: =IF(OR($B9="",$D9=""),"",IFERROR($D9*E9,"")) -> 48 | G9: =IF($B9="","",IFERROR(INDEX(材料DB!D$5:D$130,MATCH($B9,材料DB!$B$5:$B$130,0)),"材料なし")) -> 0.12 | H9: =IF(OR($B9="",$D9=""),"",IFERROR($D9*G9,"")) -> 28.8 | I9: =IF($B9="","",IFERROR(INDEX(材料DB!E$5:E$130,MATCH($B9,材料DB!$B$5:$B$130,0)),"材料なし")) -> 0.08 | J9: =IF(OR($B9="",$D9=""),"",IFERROR($D9*I9,"")) -> 19.2 | K9: =IF($B9="","",IFERROR(INDEX(材料DB!F$5:F$130,MATCH($B9,材料DB!$B$5:$B$130,0)),"材料なし")) -> 0.07 | L9: =IF(OR($B9="",$D9=""),"",IFERROR($D9*K9,"")) -> 16.8 | M9: =IF($B9="","",IFERROR(INDEX(材料DB!G$5:G$130,MATCH($B9,材料DB!$B$5:$B$130,0)),"材料なし")) -> 0.07 | N9: =IF(OR($B9="",$D9=""),"",IFERROR($D9*M9,"")) -> 16.8 | O9: =IF($B9="","",IFERROR(INDEX(材料DB!H$5:H$130,MATCH($B9,材料DB!$B$5:$B$130,0)),"材料なし")) -> 0.08 | P9: =IF(OR($B9="",$D9=""),"",IFERROR($D9*O9,"")) -> 19.2 | Q9: 資料は「板張り9+空気層90」
A10: 壁面 | B10: [18] Wood Panel 9 AS45 | C10: 共通 | D10: 244 | E10: =IF($B10="","",IFERROR(INDEX(材料DB!C$5:C$130,MATCH($B10,材料DB!$B$5:$B$130,0)),"材料なし")) -> 0.11 | F10: =IF(OR($B10="",$D10=""),"",IFERROR($D10*E10,"")) -> 26.84 | G10: =IF($B10="","",IFERROR(INDEX(材料DB!D$5:D$130,MATCH($B10,材料DB!$B$5:$B$130,0)),"材料なし")) -> 0.23 | H10: =IF(OR($B10="",$D10=""),"",IFERROR($D10*G10,"")) -> 56.12 | I10: =IF($B10="","",IFERROR(INDEX(材料DB!E$5:E$130,MATCH($B10,材料DB!$B$5:$B$130,0)),"材料なし")) -> 0.09 | J10: =IF(OR($B10="",$D10=""),"",IFERROR($D10*I10,"")) -> 21.96 | K10: =IF($B10="","",IFERROR(INDEX(材料DB!F$5:F$130,MATCH($B10,材料DB!$B$5:$B$130,0)),"材料なし")) -> 0.07 | L10: =IF(OR($B10="",$D10=""),"",IFERROR($D10*K10,"")) -> 17.08 | M10: =IF($B10="","",IFERROR(INDEX(材料DB!G$5:G$130,MATCH($B10,材料DB!$B$5:$B$130,0)),"材料なし")) -> 0.07 | N10: =IF(OR($B10="",$D10=""),"",IFERROR($D10*M10,"")) -> 17.08 | O10: =IF($B10="","",IFERROR(INDEX(材料DB!H$5:H$130,MATCH($B10,材料DB!$B$5:$B$130,0)),"材料なし")) -> 0.08 | P10: =IF(OR($B10="",$D10=""),"",IFERROR($D10*O10,"")) -> 19.52 | Q10: 資料は「板張り9+空気層45」
A11: 壁面 | B11: [64] プロセニアム開口 | C11: 共通 | D11: 78 | E11: =IF($B11="","",IFERROR(INDEX(材料DB!C$5:C$130,MATCH($B11,材料DB!$B$5:$B$130,0)),"材料なし")) -> 0.3 | F11: =IF(OR($B11="",$D11=""),"",IFERROR($D11*E11,"")) -> 23.4 | G11: =IF($B11="","",IFERROR(INDEX(材料DB!D$5:D$130,MATCH($B11,材料DB!$B$5:$B$130,0)),"材料なし")) -> 0.35 | H11: =IF(OR($B11="",$D11=""),"",IFERROR($D11*G11,"")) -> 27.3 | I11: =IF($B11="","",IFERROR(INDEX(材料DB!E$5:E$130,MATCH($B11,材料DB!$B$5:$B$130,0)),"材料なし")) -> 0.4 | J11: =IF(OR($B11="",$D11=""),"",IFERROR($D11*I11,"")) -> 31.2 | K11: =IF($B11="","",IFERROR(INDEX(材料DB!F$5:F$130,MATCH($B11,材料DB!$B$5:$B$130,0)),"材料なし")) -> 0.45 | L11: =IF(OR($B11="",$D11=""),"",IFERROR($D11*K11,"")) -> 35.1 | M11: =IF($B11="","",IFERROR(INDEX(材料DB!G$5:G$130,MATCH($B11,材料DB!$B$5:$B$130,0)),"材料なし")) -> 0.5 | N11: =IF(OR($B11="",$D11=""),"",IFERROR($D11*M11,"")) -> 39 | O11: =IF($B11="","",IFERROR(INDEX(材料DB!H$5:H$130,MATCH($B11,材料DB!$B$5:$B$130,0)),"材料なし")) -> 0.55 | P11: =IF(OR($B11="",$D11=""),"",IFERROR($D11*O11,"")) -> 42.9
A12: 扉 | B12: [66] ドア(ビニールレザー) | C12: 共通 | D12: 15 | E12: =IF($B12="","",IFERROR(INDEX(材料DB!C$5:C$130,MATCH($B12,材料DB!$B$5:$B$130,0)),"材料なし")) -> 0.1 | F12: =IF(OR($B12="",$D12=""),"",IFERROR($D12*E12,"")) -> 1.5 | G12: =IF($B12="","",IFERROR(INDEX(材料DB!D$5:D$130,MATCH($B12,材料DB!$B$5:$B$130,0)),"材料なし")) -> 0.15 | H12: =IF(OR($B12="",$D12=""),"",IFERROR($D12*G12,"")) -> 2.25 | I12: =IF($B12="","",IFERROR(INDEX(材料DB!E$5:E$130,MATCH($B12,材料DB!$B$5:$B$130,0)),"材料なし")) -> 0.2 | J12: =IF(OR($B12="",$D12=""),"",IFERROR($D12*I12,"")) -> 3 | K12: =IF($B12="","",IFERROR(INDEX(材料DB!F$5:F$130,MATCH($B12,材料DB!$B$5:$B$130,0)),"材料なし")) -> 0.25 | L12: =IF(OR($B12="",$D12=""),"",IFERROR($D12*K12,"")) -> 3.75 | M12: =IF($B12="","",IFERROR(INDEX(材料DB!G$5:G$130,MATCH($B12,材料DB!$B$5:$B$130,0)),"材料なし")) -> 0.3 | N12: =IF(OR($B12="",$D12=""),"",IFERROR($D12*M12,"")) -> 4.5 | O12: =IF($B12="","",IFERROR(INDEX(材料DB!H$5:H$130,MATCH($B12,材料DB!$B$5:$B$130,0)),"材料なし")) -> 0.3 | P12: =IF(OR($B12="",$D12=""),"",IFERROR($D12*O12,"")) -> 4.5
A13: 音響調整室 | B13: [05] ガラス窓(大版) | C13: 共通 | D13: 16 | E13: =IF($B13="","",IFERROR(INDEX(材料DB!C$5:C$130,MATCH($B13,材料DB!$B$5:$B$130,0)),"材料なし")) -> 0.18 | F13: =IF(OR($B13="",$D13=""),"",IFERROR($D13*E13,"")) -> 2.88 | G13: =IF($B13="","",IFERROR(INDEX(材料DB!D$5:D$130,MATCH($B13,材料DB!$B$5:$B$130,0)),"材料なし")) -> 0.06 | H13: =IF(OR($B13="",$D13=""),"",IFERROR($D13*G13,"")) -> 0.96 | I13: =IF($B13="","",IFERROR(INDEX(材料DB!E$5:E$130,MATCH($B13,材料DB!$B$5:$B$130,0)),"材料なし")) -> 0.04 | J13: =IF(OR($B13="",$D13=""),"",IFERROR($D13*I13,"")) -> 0.64 | K13: =IF($B13="","",IFERROR(INDEX(材料DB!F$5:F$130,MATCH($B13,材料DB!$B$5:$B$130,0)),"材料なし")) -> 0.03 | L13: =IF(OR($B13="",$D13=""),"",IFERROR($D13*K13,"")) -> 0.48 | M13: =IF($B13="","",IFERROR(INDEX(材料DB!G$5:G$130,MATCH($B13,材料DB!$B$5:$B$130,0)),"材料なし")) -> 0.02 | N13: =IF(OR($B13="",$D13=""),"",IFERROR($D13*M13,"")) -> 0.32 | O13: =IF($B13="","",IFERROR(INDEX(材料DB!H$5:H$130,MATCH($B13,材料DB!$B$5:$B$130,0)),"材料なし")) -> 0.02 | P13: =IF(OR($B13="",$D13=""),"",IFERROR($D13*O13,"")) -> 0.32
A14: 椅子 | B14: [74] 椅子(モケット張) 劇場用 | C14: 空席 | D14: 518 | E14: =IF($B14="","",IFERROR(INDEX(材料DB!C$5:C$130,MATCH($B14,材料DB!$B$5:$B$130,0)),"材料なし")) -> 0.14 | F14: =IF(OR($B14="",$D14=""),"",IFERROR($D14*E14,"")) -> 72.52 | G14: =IF($B14="","",IFERROR(INDEX(材料DB!D$5:D$130,MATCH($B14,材料DB!$B$5:$B$130,0)),"材料なし")) -> 0.25 | H14: =IF(OR($B14="",$D14=""),"",IFERROR($D14*G14,"")) -> 129.5 | I14: =IF($B14="","",IFERROR(INDEX(材料DB!E$5:E$130,MATCH($B14,材料DB!$B$5:$B$130,0)),"材料なし")) -> 0.3 | J14: =IF(OR($B14="",$D14=""),"",IFERROR($D14*I14,"")) -> 155.4 | K14: =IF($B14="","",IFERROR(INDEX(材料DB!F$5:F$130,MATCH($B14,材料DB!$B$5:$B$130,0)),"材料なし")) -> 0.3 | L14: =IF(OR($B14="",$D14=""),"",IFERROR($D14*K14,"")) -> 155.4 | M14: =IF($B14="","",IFERROR(INDEX(材料DB!G$5:G$130,MATCH($B14,材料DB!$B$5:$B$130,0)),"材料なし")) -> 0.3 | N14: =IF(OR($B14="",$D14=""),"",IFERROR($D14*M14,"")) -> 155.4 | O14: =IF($B14="","",IFERROR(INDEX(材料DB!H$5:H$130,MATCH($B14,材料DB!$B$5:$B$130,0)),"材料なし")) -> 0.3 | P14: =IF(OR($B14="",$D14=""),"",IFERROR($D14*O14,"")) -> 155.4
A15: 椅子＋人 | B15: [78] 劇場用イス + ヒト | C15: 満席 | D15: 518 | E15: =IF($B15="","",IFERROR(INDEX(材料DB!C$5:C$130,MATCH($B15,材料DB!$B$5:$B$130,0)),"材料なし")) -> 0.25 | F15: =IF(OR($B15="",$D15=""),"",IFERROR($D15*E15,"")) -> 129.5 | G15: =IF($B15="","",IFERROR(INDEX(材料DB!D$5:D$130,MATCH($B15,材料DB!$B$5:$B$130,0)),"材料なし")) -> 0.35 | H15: =IF(OR($B15="",$D15=""),"",IFERROR($D15*G15,"")) -> 181.3 | I15: =IF($B15="","",IFERROR(INDEX(材料DB!E$5:E$130,MATCH($B15,材料DB!$B$5:$B$130,0)),"材料なし")) -> 0.4 | J15: =IF(OR($B15="",$D15=""),"",IFERROR($D15*I15,"")) -> 207.2 | K15: =IF($B15="","",IFERROR(INDEX(材料DB!F$5:F$130,MATCH($B15,材料DB!$B$5:$B$130,0)),"材料なし")) -> 0.4 | L15: =IF(OR($B15="",$D15=""),"",IFERROR($D15*K15,"")) -> 207.2 | M15: =IF($B15="","",IFERROR(INDEX(材料DB!G$5:G$130,MATCH($B15,材料DB!$B$5:$B$130,0)),"材料なし")) -> 0.4 | N15: =IF(OR($B15="",$D15=""),"",IFERROR($D15*M15,"")) -> 207.2 | O15: =IF($B15="","",IFERROR(INDEX(材料DB!H$5:H$130,MATCH($B15,材料DB!$B$5:$B$130,0)),"材料なし")) -> 0.4 | P15: =IF(OR($B15="",$D15=""),"",IFERROR($D15*O15,"")) -> 207.2
A17: 全表面積 | D17: =SUMIF($C$6:$C$15,"共通",$D$6:$D$15) -> 1415 | E17: m² | G17: 椅子含む: | I17: =D17+SUMIF($C$6:$C$15,"空席",$D$6:$D$15) -> 1933 | Q17: 椅子を除く（p.7と同じ数え方）。椅子の面積も含めた部屋の全表面積 →
A18: 室容積 V | D18: 2649 | E18: m³
A20: 総吸音力 A [m²] | C20: 空席時 | F20: =SUMIF($C$6:$C$15,"共通",F$6:F$15)+SUMIF($C$6:$C$15,"空席",F$6:F$15) -> 279.62 | H20: =SUMIF($C$6:$C$15,"共通",H$6:H$15)+SUMIF($C$6:$C$15,"空席",H$6:H$15) -> 317.05 | J20: =SUMIF($C$6:$C$15,"共通",J$6:J$15)+SUMIF($C$6:$C$15,"空席",J$6:J$15) -> 300.1 | L20: =SUMIF($C$6:$C$15,"共通",L$6:L$15)+SUMIF($C$6:$C$15,"空席",L$6:L$15) -> 296.16 | N20: =SUMIF($C$6:$C$15,"共通",N$6:N$15)+SUMIF($C$6:$C$15,"空席",N$6:N$15) -> 316.18 | P20: =SUMIF($C$6:$C$15,"共通",P$6:P$15)+SUMIF($C$6:$C$15,"空席",P$6:P$15) -> 341.98
C21: 満席時 | F21: =SUMIF($C$6:$C$15,"共通",F$6:F$15)+SUMIF($C$6:$C$15,"満席",F$6:F$15) -> 336.6 | H21: =SUMIF($C$6:$C$15,"共通",H$6:H$15)+SUMIF($C$6:$C$15,"満席",H$6:H$15) -> 368.85 | J21: =SUMIF($C$6:$C$15,"共通",J$6:J$15)+SUMIF($C$6:$C$15,"満席",J$6:J$15) -> 351.9 | L21: =SUMIF($C$6:$C$15,"共通",L$6:L$15)+SUMIF($C$6:$C$15,"満席",L$6:L$15) -> 347.96 | N21: =SUMIF($C$6:$C$15,"共通",N$6:N$15)+SUMIF($C$6:$C$15,"満席",N$6:N$15) -> 367.98 | P21: =SUMIF($C$6:$C$15,"共通",P$6:P$15)+SUMIF($C$6:$C$15,"満席",P$6:P$15) -> 393.78
A22: 残響時間 T [秒] | C22: 空席時 | F22: =IF(OR(F20=0,$D$18=""),"",0.16*$D$18/F20) -> 1.5157714 | H22: =IF(OR(H20=0,$D$18=""),"",0.16*$D$18/H20) -> 1.3368238 | J22: =IF(OR(J20=0,$D$18=""),"",0.16*$D$18/J20) -> 1.4123292 | L22: =IF(OR(L20=0,$D$18=""),"",0.16*$D$18/L20) -> 1.4311183 | N22: =IF(OR(N20=0,$D$18=""),"",0.16*$D$18/N20) -> 1.3405022 | P22: =IF(OR(P20=0,$D$18=""),"",0.16*$D$18/P20) -> 1.2393707
C23: 満席時 | F23: =IF(OR(F21=0,$D$18=""),"",0.16*$D$18/F21) -> 1.25918 | H23: =IF(OR(H21=0,$D$18=""),"",0.16*$D$18/H21) -> 1.149085 | J23: =IF(OR(J21=0,$D$18=""),"",0.16*$D$18/J21) -> 1.2044331 | L23: =IF(OR(L21=0,$D$18=""),"",0.16*$D$18/L21) -> 1.218071 | N23: =IF(OR(N21=0,$D$18=""),"",0.16*$D$18/N21) -> 1.1518017 | P23: =IF(OR(P21=0,$D$18=""),"",0.16*$D$18/P21) -> 1.076337
A26: グラフ用（図3 予測された残響時間特性）
A27: 周波数 | B27: 空席時 | C27: 満席時
A28: 125 | B28: =F22 -> 1.5157714 | C28: =F23 -> 1.25918
A29: 250 | B29: =H22 -> 1.3368238 | C29: =H23 -> 1.149085
A30: 500 | B30: =J22 -> 1.4123292 | C30: =J23 -> 1.2044331
A31: 1k | B31: =L22 -> 1.4311183 | C31: =L23 -> 1.218071
A32: 2k | B32: =N22 -> 1.3405022 | C32: =N23 -> 1.1518017
A33: 4k | B33: =P22 -> 1.2393707 | C33: =P23 -> 1.076337
A43: p.7資料との照合（差が±0.01以内ならOK）
A44: 総吸音力 空席（資料値） | F44: 279.62 | H44: 317.05 | J44: 300.1 | L44: 296.16 | N44: 316.18 | P44: 341.98
A45: 総吸音力 空席（判定） | F45: =IF(ABS(F20-F44)<=0.011,"OK","ズレ") -> OK | H45: =IF(ABS(H20-H44)<=0.011,"OK","ズレ") -> OK | J45: =IF(ABS(J20-J44)<=0.011,"OK","ズレ") -> OK | L45: =IF(ABS(L20-L44)<=0.011,"OK","ズレ") -> OK | N45: =IF(ABS(N20-N44)<=0.011,"OK","ズレ") -> OK | P45: =IF(ABS(P20-P44)<=0.011,"OK","ズレ") -> OK
A46: 総吸音力 満席（資料値） | F46: 336.6 | H46: 368.85 | J46: 351.9 | L46: 347.96 | N46: 367.98 | P46: 393.78
A47: 総吸音力 満席（判定） | F47: =IF(ABS(F21-F46)<=0.011,"OK","ズレ") -> OK | H47: =IF(ABS(H21-H46)<=0.011,"OK","ズレ") -> OK | J47: =IF(ABS(J21-J46)<=0.011,"OK","ズレ") -> OK | L47: =IF(ABS(L21-L46)<=0.011,"OK","ズレ") -> OK | N47: =IF(ABS(N21-N46)<=0.011,"OK","ズレ") -> OK | P47: =IF(ABS(P21-P46)<=0.011,"OK","ズレ") -> OK
A48: 残響時間 空席（資料値） | F48: 1.52 | H48: 1.34 | J48: 1.41 | L48: 1.43 | N48: 1.34 | P48: 1.24
A49: 残響時間 空席（判定） | F49: =IF(ABS(F22-F48)<=0.011,"OK","ズレ") -> OK | H49: =IF(ABS(H22-H48)<=0.011,"OK","ズレ") -> OK | J49: =IF(ABS(J22-J48)<=0.011,"OK","ズレ") -> OK | L49: =IF(ABS(L22-L48)<=0.011,"OK","ズレ") -> OK | N49: =IF(ABS(N22-N48)<=0.011,"OK","ズレ") -> OK | P49: =IF(ABS(P22-P48)<=0.011,"OK","ズレ") -> OK
A50: 残響時間 満席（資料値） | F50: 1.26 | H50: 1.15 | J50: 1.2 | L50: 1.22 | N50: 1.15 | P50: 1.08
A51: 残響時間 満席（判定） | F51: =IF(ABS(F23-F50)<=0.011,"OK","ズレ") -> OK | H51: =IF(ABS(H23-H50)<=0.011,"OK","ズレ") -> OK | J51: =IF(ABS(J23-J50)<=0.011,"OK","ズレ") -> OK | L51: =IF(ABS(L23-L50)<=0.011,"OK","ズレ") -> OK | N51: =IF(ABS(N23-N50)<=0.011,"OK","ズレ") -> OK | P51: =IF(ABS(P23-P50)<=0.011,"OK","ズレ") -> OK
A53: 資料値は配布資料p.7 表1から転記（小数第2位で丸め済みのため±0.01の差は許容）
